File: Test data/Si ref/OptronLab/batch_example/Double peak C.txt
#Acq. time (s)=	5
#Accumulations=	1
#Range=	Off
#Autofocus=	Off
#Macrospot=	Off
#AutoExposure=	Off
#Spike filter=	Off
#Delay time (s)=	0
#Binning=	1
#Readout mode=	Signal
#DeNoise=	Off
#ICS correction=	Off
#Dark correction=	Off
#Inst. Process=	Off
#Detector Gain=	High Sensitivity
#Detector ADC=	45 kHz
#Detector temperature (°C)=	-60,1
#Instrument=	LabRAM Soleil
#Detector=	Syncerity
#Objective=	100x
#Grating=	2400 (400nm)
#ND Filter=	10% (5.7mW)
#Laser=	532nm_Edge
#Spectrometer (cm-¹)=	520,688
#Hole (µm)=	50
#Microscope=	Standard
#Laser mode=	High density
#StageXY=	75x50mm Scan+
#StageZ=	Marzhauser
#X (µm)=	0
#Y (µm)=	0
#Z (µm)=	-35,65
#Full time(s)=	5
#Project=	MA2TEC
#Sample=	Si ref
#Site=	OptronLab
#Title=	Fake double peak C
#Remark=
#Date=	22.05.2023 11:48
#Acquired=	22.05.2023 11:48:09
#AxisType[0]=Intens
#AxisUnit[0]=Cnt
#AxisType[1]=Spectr
#AxisUnit[1]=1/cm
164.9548293	64
165.6998293	78.5
166.1468293	72
167.1888293	71
167.1958293	83
168.6788293	73.5
169.4228293	76.5
170.1678293	77.5
170.9118293	81.5
171.6568293	66.5
172.3988293	70
173.1428293	66.5
173.8868293	71
174.6318293	77.5
175.1398293	70
176.1178293	78
176.8618293	63
177.1628293	76
178.3478293	73
179.0888293	64.5
179.8328293	75.5
180.5748293	57
181.3178293	70.5
182.0598293	68.5
182.8028293	84.5
183.5448293	79.5
184.2858293	59.5
185.0288293	69
185.7708293	79.5
186.5118293	67
187.2548293	83
187.9958293	71.5
188.7368293	71.5
189.4778293	72.5
190.2188293	61
190.9588293	63.5
191.7018293	65.5
192.4428293	76.5
193.1208293	63
193.1948293	66.5
194.6648293	75
195.4048293	55
196.1428293	57.5
196.1908293	61.5
197.1648293	61
198.1388293	63.5
198.2128293	70
199.1868293	65
200.5818293	70
201.3218293	70
202.0618293	58
202.7998293	70
203.5388293	69.5
204.2788293	60.5
205.0168293	58.5
205.7558293	71
206.1518293	60
207.2328293	71
207.9708293	64
208.7098293	68.5
209.4468293	64
210.1858293	58
210.9228293	66
211.6598293	64.5
212.3998293	64.5
213.1358293	65
213.8728293	61.5
214.6098293	68.5
215.3468293	67.5
216.0858293	64.5
216.8218293	61.5
217.5588293	67.5
218.2948293	62.5
219.0318293	65.5
219.7678293	64
220.1528293	57.5
221.2408293	10.5
221.9768293	73
222.7128293	62.5
223.4488293	52
224.1848293	74.5
224.9188293	67
225.6548293	63.5
226.3908293	59
227.1268293	67.5
227.8598293	82
228.5958293	73
229.3318293	63.5
230.0648293	69
230.8008293	69
231.5358293	73.5
232.2688293	71.5
233.0048293	65.5
233.7378293	63.5
234.4728293	75.5
235.2058293	62.5
235.9388293	66.5
236.1698293	85
237.4068293	80
238.1418293	67.5
238.8748293	66
239.6068293	58
240.3398293	72
241.0748293	79.5
241.8068293	58
242.5398293	74
243.2718293	62.5
244.0048293	69
244.7368293	62
245.4688293	67.5
246.2008293	61
246.9328293	70.5
247.6658293	72
248.3978293	72
249.1298293	68
249.8608293	79.5
250.5928293	74.5
251.3228293	69.5
252.0548293	68.5
252.7858293	64.5
253.5178293	82
254.2468293	69
254.9788293	71
255.7098293	71.5
256.4398293	68.5
257.1708293	68
257.8998293	64
258.6308293	80
259.3618293	63.5
260.0908293	78.5
260.8198293	78
261.5508293	71.5
262.2798293	75
263.0108293	79.5
263.7398293	65.5
264.4678293	71.5
265.1968293	58
265.9278293	62.5
266.6558293	76
267.3848293	71.5
268.1128293	74.5
268.8408293	76
269.5718293	76
270.2998293	78.5
271.0278293	74
271.7558293	83
272.1508293	62.5
273.2118293	72
273.9398293	71
274.6658293	63
275.3928293	72
276.1208293	72
276.8488293	77.5
277.5758293	75.5
278.1328293	73
279.0288293	82
279.7568293	66
280.1508293	72.5
281.2098293	76.5
281.9368293	74.5
282.6618293	76
283.3888293	67
284.1158293	74
284.8408293	73.5
285.5678293	75
286.2928293	76.5
287.0178293	83
287.7448293	77
288.4688293	83
289.1218293	73
289.9208293	85.5
290.6448293	76.5
291.3698293	85
291.2118293	82
292.8198293	84
293.5448293	77
294.2688293	85
294.9928293	70.5
295.7168293	73
296.4408293	81.5
297.1648293	70.5
297.8888293	76
298.6128293	81.5
299.3368293	76
300.0608293	75
300.1808293	77
301.5078293	84.5
302.2298293	74.5
302.9528293	74
303.6768293	75
304.3998293	66
305.1208293	72
305.8448293	79
306.5678293	68
307.2888293	77
308.0118293	80
308.7328293	61
309.4558293	60.5
310.1768293	64
310.8998293	60.5
311.6208293	59.5
312.1368293	57.5
312.2088293	67
313.7848293	58.5
314.5078293	68
315.2278293	60.5
315.9478293	67.5
316.6688293	56
317.3908293	74.5
318.1118293	47.5
318.8318293	65.5
319.5518293	54
320.2718293	66.5
320.9918293	71
321.7118293	64.5
322.4318293	62
323.1518293	57
323.8718293	58
324.5908293	50
325.3108293	62
326.0308293	63.5
326.7498293	66
327.4678293	69.5
328.1868293	59.5
328.9068293	66.5
329.6258293	65.5
330.3428293	58
331.0628293	64
331.7798293	63.5
332.4988293	61.5
333.2178293	72.5
333.9348293	68
334.1678293	77
335.3708293	61.5
336.0898293	76
336.8068293	73.5
337.5228293	62
338.2418293	79
338.9578293	78
339.6748293	74
340.1418293	79
341.1098293	70.5
341.8258293	73
342.5428293	67
343.2588293	80.5
343.9748293	70
344.6908293	84
345.4088293	77
346.1248293	88
346.8408293	84.5
347.5568293	72
348.2708293	82.5
348.9868293	76.5
349.7018293	81.5
350.4178293	83
351.1158293	78.5
351.8488293	89
352.5628293	75.5
353.2778293	97
353.2018293	87
354.7088293	94.5
355.4218293	86
356.1368293	82.5
356.8508293	103
357.5658293	118.5
358.2788293	106.5
358.2018293	100
359.7068293	105.5
360.4218293	120.5
361.1158293	104.5
361.8488293	125.5
362.5618293	127.5
363.1298293	153.5
363.9888293	153
364.7018293	194
365.1168293	170.5
366.1258293	205.5
366.8388293	234.5
367.5528293	261.5
368.2648293	293
368.9768293	342.5
369.6898293	409
370.4018293	532
371.1778293	603
371.8258293	775
372.5368293	1089.5
373.2488293	1429
373.9608293	2023
374.6708293	3201.5
375.3818293	4960.5
375.2118293	6726.5
376.8058293	7289
377.5148293	5913
378.2268293	3883
378.9378293	2554
379.6468293	1672.5
380.3588293	1166.5
381.0698293	917.5
381.7788293	714
382.4898293	551
383.1988293	450.5
383.9098293	402
384.6188293	295.5
385.3278293	291.5
386.0388293	266.5
386.7468293	224
387.4558293	205.5
388.1668293	193
388.8748293	178
389.1608293	164.5
390.2918293	153
391.0008293	146
391.7108293	148.5
392.4188293	139.5
393.1278293	132.5
393.8358293	135
394.1568293	129.5
395.2518293	116.5
395.9598293	111.5
396.6678293	107
397.3758293	103.5
398.0818293	109.5
398.7898293	98.5
399.4968293	95.5
400.2048293	100
400.9108293	97.5
401.6178293	86.5
402.3258293	101
403.0308293	89
403.7378293	77
404.4458293	81.5
405.1508293	88.5
405.8578293	80.5
406.1588293	79.5
407.2708293	83.5
407.9758293	69.5
408.6828293	78
409.3878293	85.5
410.0928293	73.5
410.7988293	67.5
411.1528293	85
412.2088293	81.5
412.1218293	70.5
413.6198293	60
414.3248293	69
415.0288293	64
415.1758293	68
416.4378293	62.5
417.1418293	70.5
417.8468293	78.5
418.5508293	70
419.2548293	59.5
419.9588293	73
420.6628293	60
421.3668293	63.5
422.0688293	59.5
422.7728293	63
423.4768293	73.5
424.1808293	61
424.8818293	57.5
425.5858293	67.5
426.2898293	65
426.9908293	60.5
427.6948293	51
428.3978293	60
429.0998293	67.5
429.8028293	64
430.1528293	60
431.2048293	61
431.9088293	61.5
432.6098293	62.5
433.3128293	54.5
433.1228293	67.5
434.7148293	56
435.4158293	60.5
436.1178293	59.5
436.8188293	60
437.5198293	67.5
438.2208293	51.5
438.9208293	63.5
439.6218293	67
440.3218293	54
441.0228293	57
441.7228293	58.5
442.4228293	54
443.1148293	61.5
443.1848293	52.5
444.1548293	55.5
445.1248293	58
445.1948293	67
446.6218293	57.5
447.3218293	57
448.0218293	55
448.7198293	54
449.4198293	60.5
450.1198293	56
450.8168293	54.5
451.5168293	56
452.1148293	52.5
452.1218293	58
453.6108293	58
454.3108293	48
455.0078293	64.5
455.7048293	49
456.4048293	64
457.1018293	54.5
457.7988293	46.5
458.4978293	54
459.1948293	53
459.8918293	62.5
460.5888293	47.5
461.2858293	46
461.9828293	50
462.6788293	51.5
463.3758293	48.5
464.0728293	66.5
464.7688293	60
465.4658293	61.5
466.1618293	46
466.8588293	67.5
467.5548293	63
468.2508293	63.5
468.9458293	56.5
469.6418293	62
470.3378293	49
470.2058293	64.5
471.7278293	66.5
472.1448293	61.5
473.1178293	62
473.1208293	65
474.5098293	62
475.1228293	64.5
475.8988293	55
476.5928293	52.5
477.2868293	60.5
477.9818293	58
478.6758293	69.5
479.3688293	67.5
480.0648293	73
480.7578293	66
481.4508293	64.5
482.1168293	68.5
482.8368293	66.5
483.5328293	72
484.2258293	68
484.9188293	66
485.6118293	69
486.3048293	54
486.9968293	57
487.6898293	62
488.3828293	63
489.0758293	66
489.7658293	71.5
490.4588293	64
491.1508293	60.5
491.1868293	59
492.1558293	72.5
493.2268293	56
493.9188293	70
494.6088293	61.5
495.3008293	61
495.2018293	64
496.1708293	63
497.3758293	68.5
498.0658293	66.5
498.7578293	60
499.4478293	63
500.1368293	70
500.8288293	65.5
501.5188293	58.5
502.2088293	77
502.8998293	86.5
503.5898293	79
504.2788293	83
504.9688293	66.5
505.6578293	78.5
506.3478293	74
507.0368293	75
507.7258293	81.5
508.4148293	87.5
508.2128293	93.5
509.1818293	97.5
510.4828293	96
511.1718293	101.5
511.8598293	118
512.5488293	121.5
513.2378293	133
513.9248293	159.5
514.1188293	177.5
515.3018293	208.5
515.9888293	253.5
516.6768293	301
517.3658293	393.5
518.0518293	511
518.7408293	707
519.4268293	1117
520.1148293	1701
520.8018293	2282.5
521.4898293	2473.5
522.1758293	2015
522.8618293	1339
523.5498293	888
524.2358293	594
524.9218293	414.5
525.6078293	349
526.2958293	277
526.9808293	223.5
527.6668293	196
528.3528293	178.5
529.0378293	131
529.1748293	142.5
530.4098293	125.5
531.0948293	119
531.7798293	105
532.4658293	107
533.1508293	104
533.8358293	90.5
534.5188293	77
535.2048293	83
535.8898293	77.5
536.5748293	94
537.2578293	83.5
537.9428293	92.5
538.6268293	78
539.3098293	87.5
539.9948293	58.5
540.6778293	75
541.3618293	75
542.0448293	74.5
542.7298293	71.5
543.4118293	64.5
544.0948293	71
544.7788293	68.5
545.4608293	64
546.1168293	70
546.8278293	54
547.5098293	65
548.1918293	57.5
548.1898293	63
549.5558293	55.5
550.2378293	62
550.9198293	70.5
551.6018293	56
552.1308293	57
552.9658293	59.5
553.6468293	59
554.3288293	58.5
555.0108293	68
555.6918293	60
556.1398293	52.5
557.0528293	59
557.7348293	63
558.4158293	48
559.0948293	56
559.7768293	41.5
560.4578293	61
561.1368293	63.5
561.8178293	51.5
562.4968293	48.5
563.1778293	58
563.8568293	55.5
564.5378293	53
565.2168293	51.5
565.8958293	54
566.5758293	56.5
567.2548293	55
567.1958293	52
568.6118293	56.5
569.2928293	48.5
569.9708293	51.5
570.6498293	44.5
571.3278293	52
572.0068293	58
572.6848293	47
573.3628293	50
574.0408293	39
574.7188293	62.5
575.3968293	54
576.0748293	43.5
576.7508293	55
577.4288293	50
578.1068293	56
578.7848293	52.5
579.4608293	53.5
580.1388293	53
580.8158293	48.5
581.4918293	52
582.1688293	46
582.8448293	54
583.5218293	50.5
584.1978293	49
584.8748293	47.5
585.5498293	45
586.2278293	41.5
586.9028293	57
587.5778293	44
588.2548293	55.5
588.9298293	47
589.6048293	41
590.2798293	53.5
590.9568293	57
591.6318293	55.5
592.3068293	45.5
592.9808293	47
593.6558293	64
594.3308293	50.5
595.0048293	47
595.6798293	51
596.3548293	53.5
597.0268293	47.5
597.7008293	46.5
598.3758293	57.5
599.0498293	53
599.1748293	41.5
600.3958293	45.5
601.0708293	53
601.7448293	54.5
602.4168293	63
603.0908293	42.5
603.7628293	44.5
604.4368293	44
605.1078293	49.5
605.7818293	49.5
606.1478293	53
607.1278293	53
607.7988293	46.5
608.4708293	58
609.1168293	50
609.8158293	48
610.4868293	55
611.1588293	60
611.8298293	49.5
612.5008293	52.5
613.1748293	64
613.8458293	55
614.5168293	42.5
615.1878293	55.5
615.8588293	47.5
616.5278293	58.5
617.1988293	48
617.8698293	46
618.5408293	51.5
619.2108293	39.5
619.8818293	45.5
620.5508293	55.5
621.2218293	55.5
621.8918293	53.5
622.5608293	43.5
623.2308293	61.5
623.8998293	60
624.5698293	61
625.2398293	51
625.9088293	51.5
626.5768293	53
627.2468293	47.5
627.9148293	47.5
628.5848293	47.5
629.2528293	53
629.9208293	57.5
630.5888293	51
631.2588293	51.5
631.9268293	56
632.5948293	41.5
633.2618293	42
633.9298293	42.5
634.5978293	67
635.2648293	56
635.9328293	48
636.6008293	56
637.2678293	55
637.9348293	55.5
638.6028293	56
639.2678293	43
639.9348293	52.5
640.6018293	58
641.2698293	48.5
641.9348293	48.5
642.6018293	56.5
643.2688293	60
643.1958293	64.5
644.6008293	60.5
645.2648293	54.5
645.9318293	47.5
646.5968293	48
647.1288293	55
647.9278293	51
648.5928293	56
649.2598293	50.5
649.1948293	58
650.5888293	61.5
651.2528293	56.5
651.9188293	45
652.1608293	49.5
653.2478293	49.5
653.9118293	57.5
654.5758293	56
655.2398293	48
655.1928293	55
656.5678293	61.5
657.2318293	43.5
657.8958293	50.5
658.5598293	44.5
659.1248293	56
659.8858293	49
660.5498293	58.5
661.2128293	61.5
661.8768293	48.5
662.5378293	47
663.2018293	56
663.1888293	51.5
664.5268293	52.5
665.1878293	61.5
665.8518293	55.5
666.5128293	63
667.1758293	53
667.8368293	48.5
668.5008293	48.5
669.1618293	57.5
669.8228293	61
670.4858293	57.5
671.1468293	51.5
671.8078293	50.5
672.4678293	51
673.1288293	59
673.7898293	47
674.4508293	53.5
675.1108293	62.5
675.7718293	50.5
676.4328293	52.5
677.0928293	61
677.1778293	48
678.1168293	57
678.2098293	55.5
679.7348293	57
680.3928293	54.5
681.0528293	47.5
681.7128293	64.5
682.1398293	64
683.0318293	55
683.6918293	53
684.3498293	61.5
685.0098293	58
685.6668293	52
686.3268293	58.5
686.9848293	46.5
687.6448293	55
688.3028293	52
688.9598293	54
689.6198293	57
690.2768293	60.5
690.9348293	57.5
691.5918293	57.5
692.2498293	52.5
692.9088293	57.5
693.5658293	66.5
694.1248293	74
694.8808293	58
695.5378293	58
696.1948293	37.5
696.8518293	56
697.5088293	58
698.1188293	61.5
698.8208293	55
699.4778293	55
700.1348293	56.5
700.7918293	56.5
701.4468293	52.5
702.1028293	61.5
702.7598293	50
703.1168293	47
704.0708293	51.5
704.7258293	54.5
705.3818293	49.5
706.0358293	50.5
706.6928293	49.5
707.3468293	50
708.0008293	53
708.6578293	48.5
709.3118293	54.5
709.9658293	59
710.6198293	49.5
711.2758293	60
711.9298293	50
712.1608293	59.5
713.2378293	46
713.8918293	55.5
714.5458293	50.5
715.1988293	48.5
715.8528293	56
716.5068293	53.5
717.1598293	55
717.1208293	54.5
718.4648293	51.5
719.1188293	51.5
719.7718293	55
720.4258293	53
721.0768293	41
721.7298293	49.5
722.1408293	49
723.0348293	50.5
723.6878293	40
724.3388293	58
724.9918293	40
725.6428293	52
726.2958293	44
726.9468293	36
727.5978293	54
728.2508293	60
728.9008293	54
729.5518293	42
730.2028293	44
730.8548293	66
731.5058293	50
732.1558293	44
732.8068293	48
733.4568293	56
734.1078293	42
734.7578293	46
735.4078293	54
736.0588293	52
736.7088293	40
737.3588293	42
738.0068293	52
738.6568293	52
739.3068293	68
739.9568293	42
740.6048293	42
741.2548293	42
741.9028293	50
742.5528293	44
743.2028293	48
743.8498293	50
744.4978293	46
745.1478293	54
745.7948293	46
746.4448293	42
747.0918293	54
747.7388293	58
748.3888293	50
749.0358293	46
749.1708293	62
750.3308293	52
750.9778293	36
751.6248293	52
752.2718293	42
752.9188293	56
753.5658293	46
754.2128293	44
754.8598293	48
755.5068293	34
756.1178293	36
756.8008293	52
757.4468293	48
758.0918293	50
758.7388293	36
759.3848293	60
760.0298293	58
760.6758293	56
761.3228293	46
761.9668293	48
762.1188293	48
763.2578293	48
763.1928293	46
764.5478293	44
765.1928293	50
765.8388293	56
766.4828293	44
767.1268293	50
767.7708293	56
768.4168293	40
769.0608293	34
769.7048293	40
770.3488293	68
770.9918293	56
771.6358293	46
772.2798293	56
772.9228293	54
773.5668293	54
774.2108293	54
774.1878293	42
775.4968293	52
776.1388293	58
776.7818293	46
777.4258293	48
778.0688293	54
778.7098293	56
779.3528293	64
779.2018293	56
780.6378293	56
781.2788293	44
781.9218293	44
782.5628293	56
783.2058293	48
783.8458293	56
784.4868293	46
785.1298293	60
785.7708293	62
786.4108293	58
787.0518293	40
787.6948293	48
788.3348293	48
788.9758293	54
789.6158293	54
790.2568293	48
790.8968293	50
791.5368293	60
792.1778293	42
792.8178293	50
793.4578293	42
794.0958293	50
794.7358293	42
795.3768293	58
796.0168293	60
796.6548293	42
797.1318293	40
797.1958293	56
798.5718293	50
799.2118293	56
799.8498293	60
800.4888293	54
801.1268293	64
801.7668293	48
802.1428293	42
803.0418293	48
803.6808293	54
804.3188293	62
804.9558293	54
805.1618293	50
806.2308293	46
806.8698293	46
807.5068293	60
808.1448293	48
808.7818293	54
809.4188293	68
810.0558293	44
810.6928293	50
811.3278293	58
811.9648293	46
812.6018293	52
813.2378293	62
813.8748293	56
814.5098293	52
815.1468293	44
815.7828293	66
816.4178293	68
816.2078293	54
817.6888293	52
818.3248293	64
818.9598293	58
819.5958293	56
820.2308293	58
820.8668293	46
821.5008293	56
822.1348293	54
822.7698293	54
823.4058293	54
824.0398293	64
824.1698293	60
825.3078293	60
825.9418293	52
826.5758293	58
827.2098293	68
827.8428293	82
828.4768293	62
829.1108293	58
829.7448293	30
830.3778293	60
831.0118293	60
831.6428293	70
832.2768293	54
832.9098293	54
833.5418293	60
834.1748293	60
834.8088293	52
835.4398293	64
836.0728293	50
836.1728293	46
837.3368293	52
837.9688293	56
838.6018293	48
839.2328293	50
839.1888293	48
840.4948293	52
841.1278293	54
841.7578293	50
842.3888293	56
843.0198293	60
843.6508293	52
844.2808293	64
844.9118293	56
845.5428293	58
846.1728293	44
846.1828293	60
847.1458293	50
848.0648293	48
848.6948293	56
849.3248293	54
849.1978293	56
850.1608293	56
851.1148293	52
851.8418293	52
852.4728293	60
853.1028293	52
853.7308293	38
854.3608293	50
854.9888293	50
855.6188293	54
856.2458293	40