File: Test data/Soleil/spectra1_Sym_rango_competo_j13057_si_wafer638nm_edge_2400 (400nm)_200 µm_100x_20% (4_1mw)_1 s_1 a_01.txt
#Acq. time (s)=	1
#Accumulations=	4
#Range (cm-¹)=	50...1000
#Windows=	4
#Auto scanning=	Off
#Autofocus=	At limit pixels
#SWIFT=	Off
#Macrospot=	Off
#AutoExposure=	Off
#Spike filter=	Single accum. (Size=3)
#Delay time (s)=	0
#Binning=	1
#Readout mode=	Signal
#DeNoise=	Off
#ICS correction=	Off
#Dark correction=	Off
#Inst. Process=	Off
#Detector Gain=	High Sensitivity
#Detector ADC=	45 kHz
#Detector temperature (°C)=	-60.1
#Instrument=	LabRAM Soleil
#Detector=	Syncerity
#Objective=	100x
#Grating=	2400 (400nm)
#ND Filter=	20% (4.1mW)
#Laser=	638nm_Edge
#Hole (µm)=	200
#Microscope=	Standard
#Laser mode=	High density
#StageXY=	QScan
#StageZ=	Marzhauser
#X (µm)=	2532.2
#Y (µm)=	151.84
#Z (µm)=	-1.15
#Full time(mm:ss)=	12:46
#Project=
#Sample=	M6_mapa_rango_completo
#Site=
#Title=	mapa_rango_competo_J13057_Si_wafer638nm_Edge_2400 (400nm)_200 µm_100x_20% (4_1mW)_1 s_4 a
#Remark=
#Date=	03.07.2023 16:53
#Acquired=	03.07.2023 16:53:48
#AxisType[0]=Intens
#AxisUnit[0]=Cnt
#AxisType[1]=Spectr
#AxisUnit[1]=1/cm
#AxisType[2]=X
#AxisUnit[2]=
#AxisType[3]=Y
#AxisUnit[3]=
50.3087	218
51.115	238
51.9211	226
52.7257	240.5
53.5316	237
54.3375	238
55.1419	227
55.9461	236.5
56.7518	230
57.5558	230
58.3598	232
59.1622	240
59.9661	246.5
60.7698	237.5
61.572	239
62.3741	221
63.1761	216.5
63.978	221
64.7798	229.5
65.5816	222
66.3818	222.5
67.1834	228
67.9834	233.5
68.7834	240
69.5832	233.5
70.383	233
71.1827	242
71.9808	234.5
72.7804	224
73.5783	238
74.3762	236
75.1755	219
75.9717	238
76.7694	242
77.5669	216
78.3629	224
79.1603	233
79.9562	237.5
80.7519	231.5
81.5476	234.5
82.3432	236
83.1387	217.5
83.9326	222
84.728	229.5
85.5217	221.5
86.3154	236.5
87.109	226.5
87.9026	226
88.696	234.5
89.4894	241
90.2812	215.5
91.073	231.5
91.8661	243
92.6577	227.5
93.4492	224.5
94.2391	227.5
95.0304	244
95.8216	230
96.6113	235
97.4009	223.5
98.1905	225
98.9799	232.5
99.7693	233.5
100.559	223.5
101.346	246.5
102.135	222.5
102.923	217.5
103.71	232
104.498	216
105.285	220.5
106.072	220.5
106.86	237
107.645	233.5
108.431	222.5
109.218	224.5
110.003	226
110.788	214.5
111.572	220.5
112.357	228
113.141	224
113.926	223.5
114.709	225.5
115.493	217
116.276	225.5
117.059	227
117.842	226
118.624	224.5
119.407	227
120.188	222.5
120.969	226
121.75	212.5
122.532	215.5
123.311	228.5
124.092	228
124.872	227
125.653	224
126.432	220
127.211	223
127.99	225.5
128.768	222.5
129.547	213
130.324	215
131.103	227
131.88	228.5
132.657	235
133.434	228.5
134.212	221
134.987	219
135.764	217.5
136.539	226
137.314	222.5
138.09	224
138.865	213.5
139.64	213.5
140.413	227.5
141.188	203.5
141.961	220
142.735	222
143.509	222
144.281	205.5
145.054	213
145.827	218.5
146.598	213
147.371	221
148.142	212
148.913	209.5
149.684	210.5
150.455	223
151.225	214
151.996	214
152.765	223.5
153.536	219.5
154.305	213.5
155.074	221
155.841	220
156.61	211
157.379	204
158.146	218.5
158.914	220.5
159.681	197.5
160.448	211.5
161.215	220
161.982	226
162.747	211.5
163.514	211.5
164.279	222.5
165.044	218.5
165.809	222
166.574	208.5
167.339	202
168.103	215
168.867	212
169.631	211.5
170.394	211
171.157	207.5
171.92	214.5
172.681	217
173.444	198.5
174.205	217
174.968	195.5
175.729	211
176.49	220.5
177.251	218.5
178.011	218.5
178.772	203.5
179.531	225.5
180.29	222
181.051	210.5
181.81	213
182.567	209.5
183.326	214
184.085	219
184.843	216.5
185.6	218
186.357	225
187.114	217
187.871	216.5
188.628	217.5
189.383	223
190.14	210
190.896	220.5
191.651	218.5
192.406	210
193.161	218
193.916	208
194.669	229
195.423	204
196.177	203
196.931	217.5
197.684	226
198.437	211.5
199.188	216
199.941	205
200.693	206
201.444	214
202.195	205.5
202.947	223
203.698	209.5
204.449	219.5
205.198	212
205.949	207
206.698	216
207.448	216.5
208.197	210
208.946	206.5
209.694	199.5
210.443	214
211.19	202.5
211.937	206
212.685	225
213.432	217.5
214.179	208.5
214.926	216
215.672	199.5
216.419	210.5
217.164	212
217.91	203.5
218.655	213
219.399	210
220.144	207
220.887	215
221.632	212
222.376	214
223.119	203.5
223.862	214.5
224.606	211.5
225.347	206
226.09	214.5
226.832	203.5
227.574	211.5
228.315	218.5
229.056	208.5
229.798	207.5
230.537	211.5
231.277	213
232.018	202.5
232.758	210.5
233.497	219
234.237	199.5
234.974	196.5
235.714	206
236.451	204.5
237.189	216
237.928	208
238.664	208
239.402	200.5
240.139	198.5
240.875	206
241.612	214
242.348	196.5
243.084	194
243.819	200
244.555	195.5
245.289	198.5
246.024	210.5
246.758	192.5
247.492	208.5
248.225	198
248.959	217
249.693	200.5
250.425	210.5
251.158	202.5
251.89	209.5
252.622	207.5
253.354	206.5
254.085	206
254.817	211
255.547	205
256.278	203
257.008	195.5
257.738	206.5
258.468	207.5
259.198	199.5
259.926	194.5
260.656	208
261.384	192.5
262.112	193.5
262.84	205
263.568	183.5
264.296	213
265.023	197.5
265.75	203.5
266.476	220
267.203	196.5
267.929	211.5
268.655	195
269.38	218.5
270.106	207.5
270.83	197
271.554	210.5
272.28	193
273.004	193
273.727	208.5
274.451	197
275.174	202
275.897	209
276.619	207.5
277.341	193
278.064	206.5
278.786	207.5
279.506	205
280.228	197.5
280.949	195.5
281.669	211
282.39	193.5
283.11	196
283.83	201
284.55	195
285.269	199
285.987	201.5
286.706	192
287.424	198.5
288.143	189.5
288.861	192
289.578	197.5
290.296	197.5
291.012	203
291.729	204
292.446	213.5
293.161	210
293.877	200.5
294.593	212.5
295.308	215
296.023	197
296.737	207.5
297.452	214.5
298.167	221.5
298.88	215.5
299.592	223
300.307	230
301.02	220.5
301.732	230
302.445	247
303.156	226.5
303.869	234
304.58	232.5
305.291	227
306.002	223.5
306.713	203.5
307.423	212.5
308.133	216
308.843	196.5
309.553	218
310.262	207
310.971	202
311.68	201.024
312.388	212.504
313.096	205.465
313.803	203.06
314.512	196.302
315.219	198.588
315.926	196.842
316.632	204.467
317.339	206.401
318.044	199.627
318.751	192.681
319.456	195.768
320.162	195.624
320.867	189.247
321.571	193.679
322.276	192.632
322.979	184.587
323.683	188.263
324.386	181.183
325.09	190.685
325.793	189.058
326.496	177.893
327.198	182.524
327.9	185.577
328.603	189.175
329.304	179.096
330.005	177.297
330.706	185.054
331.407	183.584
332.107	180.827
332.807	182.053
333.507	178.841
334.207	175.514
334.906	172.206
335.606	183.569
336.304	180.629
337.002	171.771
337.7	181.077
338.398	177.409
339.095	164.357
339.793	170.169
340.489	178.844
341.187	177.628
341.883	164.678
342.579	171.482
343.275	171.376
343.971	169.142
344.666	180.184
345.361	174.92
346.056	176.444
346.75	173.945
347.444	163.675
348.138	163.581
348.832	162.882
349.525	166.224
350.219	168.91
350.911	165.78
351.604	167.985
352.296	168.479
352.988	163.373
353.679	163.463
354.371	162.065
355.062	163.544
355.752	163.037
356.443	163.506
357.133	163.491
357.822	156.897
358.512	165.9
359.201	164.532
359.89	161.8
360.579	159.58
361.267	159.55
361.956	154.951
362.644	167.545
363.331	167.475
364.018	159.149
364.705	151.859
365.392	158.04
366.079	152.828
366.766	157.456
367.451	157.616
368.137	151.744
368.822	156.918
369.507	156.199
370.192	164.224
370.876	154.409
371.561	157.222
372.244	160.491
372.927	162.522
373.612	156.048
374.294	154.657
374.977	156.4
375.66	149.026
376.342	155.639
377.024	155.051
377.706	146.809
378.387	159.344
379.067	154.888
379.748	151.513
380.43	147.182
381.109	162.86
381.789	152.935
382.469	161.844
383.148	143.987
383.828	152.605
384.506	152.466
385.185	148.203
385.863	153.697
386.541	151.222
387.218	148.435
387.896	148.537
388.572	155.292
389.25	142.085
389.926	149.663
390.602	146.038
391.278	153.486
391.954	147.168
392.63	152.411
393.304	150.635
393.98	143.035
394.654	149.733
395.328	142.787
396.002	146.575
396.676	145.496
397.349	141.114
398.023	138.939
398.695	152.242
399.367	146.402
400.04	142.198
400.712	138.945
401.383	142.936
402.055	149.062
402.726	147.651
403.396	148.831
404.067	147.657
404.737	135.759
405.408	142.805
406.077	138.741
406.747	147.936
407.416	143.567
408.085	134.642
408.753	135.816
409.421	142.796
410.089	143.719
410.756	141.278
411.425	135.586
412.092	143.093
412.759	142.237
413.424	141.189
414.091	139.582
414.756	140.637
415.423	132.607
416.088	140.293
416.754	136.859
417.419	139.836
418.082	140.157
418.747	134.27
419.411	128.806
419.802	143
420.512	135.5
421.222	134.5
421.931	140.5
422.64	126.5
423.35	127
424.058	142
424.767	131
425.474	141
426.182	138
426.889	136.5
427.597	139
428.304	136
429.011	131.5
429.717	136
430.422	133.5
431.129	138
431.834	133
432.54	138
433.245	129
433.95	135
434.655	133
435.359	127.5
436.062	142
436.767	133.5
437.47	132
438.173	121
438.876	116
439.579	128
440.28	128.5
440.983	113
441.684	132
442.387	114
443.088	122.5
443.789	110
444.49	120
445.189	121.5
445.89	120.5
446.59	118
447.289	112
447.988	118.5
448.688	115
449.387	113
450.086	126
450.783	112.5
451.482	104
452.18	113
452.877	110
453.574	117
454.272	110.5
454.967	105.5
455.665	110
456.36	100
457.056	108
457.751	110
458.447	101
459.142	113.5
459.836	111
460.532	101.5
461.225	93.5
461.919	105
462.613	107.5
463.306	106
464	97
464.692	96.5
465.385	97.5
466.077	94.5
466.769	98
467.461	102
468.153	100
468.845	95.5
469.535	91
470.225	94
470.916	94
471.606	105.5
472.296	86
472.985	86.5
473.675	102.5
474.365	93.5
475.053	92.5
475.741	92
476.429	86.5
477.117	87
477.806	84
478.492	94
479.18	90
479.867	96
480.553	88
481.239	86
481.926	90
482.612	80.5
483.297	85.5
483.983	88
484.667	82.5
485.352	87
486.036	74.5
486.721	78
487.404	84.5
488.088	83.5
488.771	71
489.454	79.5
490.136	82
490.819	86
491.502	73.5
492.184	75.5
492.865	70
493.546	75.5
494.229	78
494.91	72
495.589	74
496.27	75.5
496.95	70
497.63	77.5
498.309	70
498.988	72
499.667	70.5
500.346	74
501.025	77
501.702	70.5
502.381	82.5
503.059	79.5
503.736	79.5
504.413	90
505.089	87.5
505.766	93
506.443	97.5
507.119	103
507.794	120.5
508.47	137
509.145	142
509.819	152
510.494	169.5
511.168	191.5
511.843	212.5
512.517	242
513.19	276
513.863	297
514.536	341
515.208	364
515.882	425
516.554	470
517.225	464.5
517.897	508
518.569	529
519.239	511.5
519.911	519
520.581	539.5
521.251	507.5
521.921	521.5
522.591	491.5
523.26	507
523.93	457.5
524.598	432
525.266	408.5
525.935	366
526.603	327
527.271	286.5
527.939	267.5
528.606	229
529.273	192
529.94	179.5
530.606	163.5
531.272	142
531.938	132
532.603	124
533.27	110.5
533.934	105.5
534.599	98.5
535.264	91.5
535.928	89
536.592	83
537.256	81
537.919	86.5
538.582	73
539.245	75.5
539.908	78
540.571	72.5
541.232	73
541.895	78
542.556	84.5
543.217	72.5
543.878	71.5
544.539	72
545.199	72
545.86	80
546.519	71.5
547.179	78
547.838	82.5
548.498	79.5
549.157	78.5
549.815	87
550.474	78.5
551.132	77
551.789	89.5
552.447	75.5
553.104	75
553.76	84.5
554.418	93
555.074	84.5
555.73	89
556.385	90
557.041	88.5
557.697	94
558.351	76
559.006	89.5
559.661	84
560.315	92
560.969	95
561.622	96.5
562.276	99.5
562.928	102
563.582	90.5
564.235	90.5
564.887	82.5
565.539	94
566.19	87
566.842	93.5
567.493	84
568.143	100
568.794	94.5
569.445	90
570.095	100
570.745	89.5
571.394	100
572.043	102
572.692	102
573.341	88.5
573.99	103
574.638	93.5
575.286	107
575.934	99.5
576.581	97
577.229	98.5
577.876	100.5
578.521	103
579.168	107
579.814	105
580.46	100.5
581.106	101
581.751	106
582.395	110
583.04	105
583.684	120.5
584.329	112.5
584.973	103
585.616	109.5
586.26	110
586.902	120
587.545	115.5
588.187	116.5
588.83	115
589.472	107.5
590.113	118
590.755	116.5
591.396	113.5
592.036	124
592.677	118.5
593.318	122
593.958	122
594.597	128.5
595.237	120
595.875	130
596.515	125.5
597.154	121
597.792	127.5
598.431	121
599.067	126.5
599.706	138
600.342	114.5
600.981	134.5
601.617	133
602.254	137
602.889	129
603.526	135.5
604.161	136
604.797	131.5
605.432	134.5
606.067	128
606.7	132
607.335	136
607.97	131.5
608.603	140
609.236	139.5
609.87	136
610.503	140
611.136	137.5
611.768	146
612.401	146.5
613.032	137.5
613.664	135
614.295	153.5
614.925	142
615.556	140.436
616.188	141.173
616.818	144.256
617.447	148.056
618.077	136.686
618.707	140.131
619.335	134.978
619.965	135.109
620.593	137.949
621.221	136.585
621.849	140.933
622.477	142.954
623.105	138.436
623.731	135.992
624.359	142.974
624.986	150.544
625.612	141.463
626.238	132.599
626.863	146.012
627.489	144.099
628.114	144.811
628.74	137.799
629.365	142.865
629.989	145.487
630.613	145.924
631.237	149.358
631.86	151.165
632.484	143.992
633.107	139.522
633.73	140.208
634.353	147.043
634.975	147.46
635.597	142.72
636.219	147.469
636.84	147.191
637.461	147.421
638.082	142.069
638.704	149.614
639.323	141.107
639.944	145.337
640.564	147.221
641.183	140.829
641.803	147.674
642.421	152.901
643.04	144.068
643.658	151.101
644.278	145.749
644.895	148.392
645.513	146.691
646.13	155.373
646.747	145.958
647.364	146.159
647.981	146.321
648.597	154.905
649.213	149.786
649.829	149.275
650.444	147.629
651.06	158.971
651.675	157.272
652.289	154.096
652.904	151.661
653.518	155.695
654.132	158.358
654.745	154.98
655.332	154.857
655.991	149.408
656.65	157.72
657.308	151.701
657.966	153.023
658.624	158.541
659.282	159.883
659.938	160.36
660.596	156.454
661.253	161.416
661.909	163.463
662.565	155.702
663.222	153.484
663.878	160.733
664.534	156.22
665.189	157.784
665.843	163.301
666.498	163.583
667.152	156.053
667.807	156.709
668.461	155.462
669.114	155.709
669.768	163.141
670.421	156.746
671.074	161.179
671.727	170.296
672.38	160.274
673.031	161.746
673.683	165.74
674.335	169.287
674.987	161.145
675.638	167.867
676.288	165.24
676.939	164.09
677.589	166.712
678.239	164.059
678.89	173.014
679.539	163.614
680.188	166.406
680.838	163.584
681.485	169.43
682.134	168.481
682.782	175.542
683.431	180.139
684.079	167.321
684.726	178.179
685.372	172.913
686.02	171.163
686.667	177.441
687.313	171.453
687.959	173.149
688.604	176.616
689.25	171.459
689.896	173.209
690.542	172.045
691.186	179.661
691.83	175.213
692.475	181.346
693.119	179.84
693.762	180.711
694.406	171.905
695.05	173.298
695.692	182.174
696.335	186.526
696.978	179.053
697.621	180.36
698.262	175.633
698.904	182.083
699.546	182.067
700.187	187.627
700.827	183.147
701.468	181.854
702.108	189.301
702.749	172.445
703.388	179.819
704.028	175.776
704.667	198.088
705.306	192.914
705.945	193.336
706.584	182.616
707.222	196.741
707.861	190.018
708.498	194.84
709.135	189.352
709.773	198.097
710.41	185.063
711.047	184.78
711.684	194.052
712.319	200.528
712.956	194.333
713.592	196.749
714.227	200.109
714.862	208.896
715.498	198.54
716.131	205.006
716.767	202
717.4	216.5
718.034	221.5
718.668	212.5
719.301	213.5
719.933	222.5
720.567	225.5
721.199	224.5
721.832	222
722.464	233
723.096	226
723.727	242
724.359	231.5
724.989	234.5
725.621	226
726.251	226
726.881	224
727.511	210
728.14	212.5
728.77	216
729.399	210
730.029	206
730.657	195.5
731.286	212
731.913	202
732.541	201
733.17	214
733.797	212.5
734.423	204
735.05	202.5
735.677	204.5
736.304	202.5
736.929	206.5
737.556	200.5
738.181	205
738.806	193
739.431	194
740.056	206
740.68	199
741.305	192.5
741.928	201
742.552	196
743.175	208
743.798	195
744.422	204
745.045	204
745.667	203.5
746.289	213
746.91	202
747.532	199
748.154	201
748.775	210
749.395	200
750.017	200.5
750.637	198
751.257	205
751.877	206.5
752.495	218
753.115	202
753.734	207.5
754.353	205.5
754.972	199.5
755.59	204.5
756.207	205.5
756.825	211.5
757.443	210
758.06	187.5
758.677	208.5
759.293	204.5
759.91	204
760.526	199.5
761.142	197.5
761.758	195.5
762.373	198.5
762.988	212.5
763.603	196
764.218	200
764.831	203.5
765.446	209
766.059	207
766.673	210.5
767.286	210.5
767.899	201.5
768.512	204
769.124	202.5
769.736	210
770.349	218
770.96	205
771.572	207
772.182	204
772.794	203
773.404	208
774.015	210
774.625	193.5
775.235	189
775.845	208
776.453	209.5
777.063	203
777.671	212.5
778.279	206.5
778.888	213.5
779.496	201.5
780.104	210.5
780.712	206.5
781.319	212
781.925	219.5
782.532	212.5
783.138	218
783.745	210.5
784.351	205
784.956	205.5
785.561	218
786.168	216.5
786.773	215.5
787.376	210
787.981	208.5
788.586	209
789.189	206
789.792	220
790.396	205
790.999	215
791.602	199.5
792.204	201.5
792.807	203.5
793.408	198
794.01	225
794.611	200.5
795.213	203
795.814	214.5
796.414	199
797.014	212
797.616	216
798.216	228.5
798.814	203
799.414	210
800.014	215.5
800.612	209.5
801.21	211
801.809	223.5
802.407	218.5
803.005	219
803.602	211.5
804.2	219.5
804.797	201
805.393	198.5
805.99	206
806.586	196.5
807.183	201.5
807.778	202.5
808.373	215
808.969	213
809.564	208.5
810.158	213.5
810.753	217
811.347	222
811.941	211
812.534	209
813.127	209
813.721	215
814.314	211.5
814.906	206
815.499	223.5
816.091	210
816.682	216.5
817.274	220
817.865	210
818.456	215
819.047	205.5
819.637	231
820.227	202.5
820.817	213.5
821.407	221
821.997	216
822.586	211
823.175	207.5
823.764	212.5
824.352	225
824.941	211.5
825.528	214.5
826.116	214
826.703	216
827.289	224.5
827.876	225
828.463	203
829.049	207.5
829.636	212.5
830.221	218
830.807	214.5
831.392	219
831.977	224.5
832.562	220.5
833.147	218.5
833.73	214.5
834.315	224
834.899	220
835.482	210
836.064	221
836.648	219.5
837.231	223.5
837.813	217
838.395	214.5
838.977	215.5
839.558	213
840.14	223.5
840.721	217.5
841.302	203.5
841.882	204
842.463	224
843.043	220
843.622	222.5
844.202	215
844.78	220
845.36	215.5
845.939	215.5
846.518	215.5
847.095	228
847.673	221.5
848.25	223.5
848.829	236.5
849.406	222
849.983	223
850.558	231
851.135	221.5
851.712	213
852.287	208
852.863	222.5
853.438	232.5
854.013	224.5
854.587	218
855.163	217.5
855.736	215
856.31	216
856.884	218
857.458	211.5
858.031	220.5
858.603	221
859.177	217
859.749	217.5
860.321	219.5
860.893	231
861.465	227.5
862.036	218
862.608	222
863.179	221.5
863.749	224
864.32	223.5
864.889	211
865.459	218
866.028	214.5
866.598	225
867.167	220.5
867.736	220
868.304	238
868.872	230
869.44	226
870.009	234.5
870.576	221.5
870.908	222.5
871.522	221.5
872.135	228.5
872.747	226.5
873.36	223.5
873.972	228.5
874.585	224.5
875.196	222.5
875.808	221.5
876.419	226.5
877.03	225
877.641	236
878.252	213
878.863	225
879.472	219.5
880.083	220
880.692	238.5
881.301	241
881.911	224
882.52	215
883.128	220
883.737	228.5
884.344	232
884.952	220.5
885.559	221.5
886.167	226
886.774	224
887.382	233.5
887.988	228.5
888.594	224.5
889.2	230.5
889.806	229
890.412	227.5
891.017	229.5
891.623	223
892.227	237
892.832	220.5
893.436	244.5
894.04	219.5
894.644	231.5
895.248	224.5
895.851	222.5
896.454	225.5
897.058	224.5
897.66	241.5
898.263	236.5
898.864	221
899.466	225.5
900.068	223
900.67	236
901.271	227.5
901.872	231.5
902.471	231.5
903.072	232
903.673	223
904.272	238.5
904.872	233
905.471	232.5
906.07	240.5
906.669	222.5
907.268	230
907.866	219
908.464	226
909.061	234.5
909.659	235.5
910.257	234.5
910.854	218
911.452	237
912.048	228.5
912.644	224.5
913.24	219.5
913.836	231.5
914.432	235
915.027	234
915.622	252.5
916.216	220
916.812	219
917.406	233
917.999	228
918.593	237.5
919.188	240.5
919.78	232
920.373	232
920.966	240
921.559	237
922.151	240.5
922.744	225
923.04	218