File: Test data/Soleil/spectra1_rango_competo_j13057_si_wafer638nm_edge_2400 (400nm)_200 µm_100x_20% (4_1mw)_1 s_1 a_01.txt
#Acq. time (s)=	1
#Accumulations=	4
#Range (cm-¹)=	50...1000
#Windows=	4
#Auto scanning=	Off
#Autofocus=	At limit pixels
#SWIFT=	Off
#Macrospot=	Off
#AutoExposure=	Off
#Spike filter=	Single accum. (Size=3)
#Delay time (s)=	0
#Binning=	1
#Readout mode=	Signal
#DeNoise=	Off
#ICS correction=	Off
#Dark correction=	Off
#Inst. Process=	Off
#Detector Gain=	High Sensitivity
#Detector ADC=	45 kHz
#Detector temperature (°C)=	-60.1
#Instrument=	LabRAM Soleil
#Detector=	Syncerity
#Objective=	100x
#Grating=	2400 (400nm)
#ND Filter=	20% (4.1mW)
#Laser=	638nm_Edge
#Hole (µm)=	200
#Microscope=	Standard
#Laser mode=	High density
#StageXY=	QScan
#StageZ=	Marzhauser
#X (µm)=	2532.2
#Y (µm)=	151.84
#Z (µm)=	-1.15
#Full time(mm:ss)=	12:46
#Project=
#Sample=	M6_mapa_rango_completo
#Site=
#Title=	mapa_rango_competo_J13057_Si_wafer638nm_Edge_2400 (400nm)_200 µm_100x_20% (4_1mW)_1 s_4 a
#Remark=
#Date=	03.07.2023 16:53
#Acquired=	03.07.2023 16:53:48
#AxisType[0]=Intens
#AxisUnit[0]=Cnt
#AxisType[1]=Spectr
#AxisUnit[1]=1/cm
#AxisType[2]=X
#AxisUnit[2]=
#AxisType[3]=Y
#AxisUnit[3]=
50.3087	218
51.115	238
51.9211	226
52.7257	240.5
53.5316	237
54.3375	238
55.1419	227
55.9461	236.5
56.7518	230
57.5558	230
58.3598	232
59.1622	240
59.9661	246.5
60.7698	237.5
61.572	239
62.3741	221
63.1761	216.5
63.978	221
64.7798	229.5
65.5816	222
66.3818	222.5
67.1834	228
67.9834	233.5
68.7834	240
69.5832	233.5
70.383	233
71.1827	242
71.9808	234.5
72.7804	224
73.5783	238
74.3762	236
75.1755	219
75.9717	238
76.7694	242
77.5669	216
78.3629	224
79.1603	233
79.9562	237.5
80.7519	231.5
81.5476	234.5
82.3432	236
83.1387	217.5
83.9326	222
84.728	229.5
85.5217	221.5
86.3154	236.5
87.109	226.5
87.9026	226
88.696	234.5
89.4894	241
90.2812	215.5
91.073	231.5
91.8661	243
92.6577	227.5
93.4492	224.5
94.2391	227.5
95.0304	244
95.8216	230
96.6113	235
97.4009	223.5
98.1905	225
98.9799	232.5
99.7693	233.5
100.559	223.5
101.346	246.5
102.135	222.5
102.923	217.5
103.71	232
104.498	216
105.285	220.5
106.072	220.5
106.86	237
107.645	233.5
108.431	222.5
109.218	224.5
110.003	226
110.788	214.5
111.572	220.5
112.357	228
113.141	224
113.926	223.5
114.709	225.5
115.493	217
116.276	225.5
117.059	227
117.842	226
118.624	224.5
119.407	227
120.188	222.5
120.969	226
121.75	212.5
122.532	215.5
123.311	228.5
124.092	228
124.872	227
125.653	224
126.432	220
127.211	223
127.99	225.5
128.768	222.5
129.547	213
130.324	215
131.103	227
131.88	228.5
132.657	235
133.434	228.5
134.212	221
134.987	219
135.764	217.5
136.539	226
137.314	222.5
138.09	224
138.865	213.5
139.64	213.5
140.413	227.5
141.188	203.5
141.961	220
142.735	222
143.509	222
144.281	205.5
145.054	213
145.827	218.5
146.598	213
147.371	221
148.142	212
148.913	209.5
149.684	210.5
150.455	223
151.225	214
151.996	214
152.765	223.5
153.536	219.5
154.305	213.5
155.074	221
155.841	220
156.61	211
157.379	204
158.146	218.5
158.914	220.5
159.681	197.5
160.448	211.5
161.215	220
161.982	226
162.747	211.5
163.514	211.5
164.279	222.5
165.044	218.5
165.809	222
166.574	208.5
167.339	202
168.103	215
168.867	212
169.631	211.5
170.394	211
171.157	207.5
171.92	214.5
172.681	217
173.444	198.5
174.205	217
174.968	195.5
175.729	211
176.49	220.5
177.251	218.5
178.011	218.5
178.772	203.5
179.531	225.5
180.29	222
181.051	210.5
181.81	213
182.567	209.5
183.326	214
184.085	219
184.843	216.5
185.6	218
186.357	225
187.114	217
187.871	216.5
188.628	217.5
189.383	223
190.14	210
190.896	220.5
191.651	218.5
192.406	210
193.161	218
193.916	208
194.669	229
195.423	204
196.177	203
196.931	217.5
197.684	226
198.437	211.5
199.188	216
199.941	205
200.693	206
201.444	214
202.195	205.5
202.947	223
203.698	209.5
204.449	219.5
205.198	212
205.949	207
206.698	216
207.448	216.5
208.197	210
208.946	206.5
209.694	199.5
210.443	214
211.19	202.5
211.937	206
212.685	225
213.432	217.5
214.179	208.5
214.926	216
215.672	199.5
216.419	210.5
217.164	212
217.91	203.5
218.655	213
219.399	210
220.144	207
220.887	215
221.632	212
222.376	214
223.119	203.5
223.862	214.5
224.606	211.5
225.347	206
226.09	214.5
226.832	203.5
227.574	211.5
228.315	218.5
229.056	208.5
229.798	207.5
230.537	211.5
231.277	213
232.018	202.5
232.758	210.5
233.497	219
234.237	199.5
234.974	196.5
235.714	206
236.451	204.5
237.189	216
237.928	208
238.664	208
239.402	200.5
240.139	198.5
240.875	206
241.612	214
242.348	196.5
243.084	194
243.819	200
244.555	195.5
245.289	198.5
246.024	210.5
246.758	192.5
247.492	208.5
248.225	198
248.959	217
249.693	200.5
250.425	210.5
251.158	202.5
251.89	209.5
252.622	207.5
253.354	206.5
254.085	206
254.817	211
255.547	205
256.278	203
257.008	195.5
257.738	206.5
258.468	207.5
259.198	199.5
259.926	194.5
260.656	208
261.384	192.5
262.112	193.5
262.84	205
263.568	183.5
264.296	213
265.023	197.5
265.75	203.5
266.476	220
267.203	196.5
267.929	211.5
268.655	195
269.38	218.5
270.106	207.5
270.83	197
271.554	210.5
272.28	193
273.004	193
273.727	208.5
274.451	197
275.174	202
275.897	209
276.619	207.5
277.341	193
278.064	206.5
278.786	207.5
279.506	205
280.228	197.5
280.949	195.5
281.669	211
282.39	193.5
283.11	196
283.83	201
284.55	195
285.269	199
285.987	201.5
286.706	192
287.424	198.5
288.143	189.5
288.861	192
289.578	197.5
290.296	197.5
291.012	203
291.729	204
292.446	213.5
293.161	210
293.877	200.5
294.593	212.5
295.308	215
296.023	197
296.737	207.5
297.452	214.5
298.167	221.5
298.88	215.5
299.592	223
300.307	230
301.02	220.5
301.732	230
302.445	247
303.156	226.5
303.869	234
304.58	232.5
305.291	227
306.002	223.5
306.713	203.5
307.423	212.5
308.133	216
308.843	196.5
309.553	218
310.262	207
310.971	202
311.68	201.024
312.388	212.504
313.096	205.465
313.803	203.06
314.512	196.302
315.219	198.588
315.926	196.842
316.632	204.467
317.339	206.401
318.044	199.627
318.751	192.681
319.456	195.768
320.162	195.624
320.867	189.247
321.571	193.679
322.276	192.632
322.979	184.587
323.683	188.263
324.386	181.183
325.09	190.685
325.793	189.058
326.496	177.893
327.198	182.524
327.9	185.577
328.603	189.175
329.304	179.096
330.005	177.297
330.706	185.054
331.407	183.584
332.107	180.827
332.807	182.053
333.507	178.841
334.207	175.514
334.906	172.206
335.606	183.569
336.304	180.629
337.002	171.771
337.7	181.077
338.398	177.409
339.095	164.357
339.793	170.169
340.489	178.844
341.187	177.628
341.883	164.678
342.579	171.482
343.275	171.376
343.971	169.142
344.666	180.184
345.361	174.92
346.056	176.444
346.75	173.945
347.444	163.675
348.138	163.581
348.832	162.882
349.525	166.224
350.219	168.91
350.911	165.78
351.604	167.985
352.296	168.479
352.988	163.373
353.679	163.463
354.371	162.065
355.062	163.544
355.752	163.037
356.443	163.506
357.133	163.491
357.822	156.897
358.512	165.9
359.201	164.532
359.89	161.8
360.579	159.58
361.267	159.55
361.956	154.951
362.644	167.545
363.331	167.475
364.018	159.149
364.705	151.859
365.392	158.04
366.079	152.828
366.766	157.456
367.451	157.616
368.137	151.744
368.822	156.918
369.507	156.199
370.192	164.224
370.876	154.409
371.561	157.222
372.244	160.491
372.927	162.522
373.612	156.048
374.294	154.657
374.977	156.4
375.66	149.026
376.342	155.639
377.024	155.051
377.706	146.809
378.387	159.344
379.067	154.888
379.748	151.513
380.43	147.182
381.109	162.86
381.789	152.935
382.469	161.844
383.148	143.987
383.828	152.605
384.506	152.466
385.185	148.203
385.863	153.697
386.541	151.222
387.218	148.435
387.896	148.537
388.572	155.292
389.25	142.085
389.926	149.663
390.602	146.038
391.278	153.486
391.954	147.168
392.63	152.411
393.304	150.635
393.98	143.035
394.654	149.733
395.328	142.787
396.002	146.575
396.676	145.496
397.349	141.114
398.023	138.939
398.695	152.242
399.367	146.402
400.04	142.198
400.712	138.945
401.383	142.936
402.055	149.062
402.726	147.651
403.396	148.831
404.067	147.657
404.737	135.759
405.408	142.805
406.077	138.741
406.747	147.936
407.416	143.567
408.085	134.642
408.753	135.816
409.421	142.796
410.089	143.719
410.756	141.278
411.425	135.586
412.092	143.093
412.759	142.237
413.424	141.189
414.091	139.582
414.756	140.637
415.423	132.607
416.088	140.293
416.754	136.859
417.419	139.836
418.082	140.157
418.747	134.27
419.411	128.806
419.802	143
420.512	135.5
421.222	134.5
421.931	140.5
422.64	126.5
423.35	127
424.058	142
424.767	131
425.474	141
426.182	138
426.889	136.5
427.597	139
428.304	136
429.011	131.5
429.717	136
430.422	133.5
431.129	138
431.834	133
432.54	138
433.245	129
433.95	135
434.655	133
435.359	127.5
436.062	142
436.767	133.5
437.47	132
438.173	121
438.876	116
439.579	128
440.28	128.5
440.983	113
441.684	132
442.387	114
443.088	122.5
443.789	110
444.49	120
445.189	121.5
445.89	120.5
446.59	118
447.289	112
447.988	118.5
448.688	115
449.387	113
450.086	126
450.783	112.5
451.482	104
452.18	113
452.877	110
453.574	117
454.272	110.5
454.967	105.5
455.665	110
456.36	100
457.056	108
457.751	110
458.447	101
459.142	113.5
459.836	111
460.532	101.5
461.225	93.5
461.919	105
462.613	107.5
463.306	106
464	97
464.692	96.5
465.385	97.5
466.077	94.5
466.769	98
467.461	102
468.153	100
468.845	95.5
469.535	91
470.225	94
470.916	94
471.606	105.5
472.296	86
472.985	86.5
473.675	102.5
474.365	93.5
475.053	92.5
475.741	92
476.429	86.5
477.117	87
477.806	84
478.492	94
479.18	90
479.867	96
480.553	88
481.239	86
481.926	90
482.612	80.5
483.297	85.5
483.983	88
484.667	82.5
485.352	87
486.036	74.5
486.721	78
487.404	84.5
488.088	83.5
488.771	71
489.454	79.5
490.136	82
490.819	86
491.502	73.5
492.184	75.5
492.865	70
493.546	75.5
494.229	78
494.91	72
495.589	74
496.27	75.5
496.95	70
497.63	77.5
498.309	70
498.988	72
499.667	70.5
500.346	74
501.025	77
501.702	70.5
502.381	82.5
503.059	79.5
503.736	79.5
504.413	90
505.089	87.5
505.766	93
506.443	97.5
507.119	103
507.794	120.5
508.47	137
509.145	142
509.819	152
510.494	169.5
511.168	191.5
511.843	212.5
512.517	242
513.19	276
513.863	297
514.536	341
515.208	364
515.882	425
516.554	470
517.225	464.5
517.897	508
518.569	529
519.239	511.5
519.911	519
520.581	516.5
521.251	516.5
521.921	484
522.591	469
523.26	481.5
523.93	441
524.598	446.5
525.266	438
525.935	394.5
526.603	420
527.271	398
527.939	384
528.606	378
529.273	355
529.94	366.5
530.606	360.5
531.272	330.5
531.938	340
532.603	326.5
533.27	312.5
533.934	306
534.599	305
535.264	311.5
535.928	295.5
536.592	285.5
537.256	279.5
537.919	264
538.582	277.5
539.245	266.5
539.908	262.5
540.571	260.5
541.232	251
541.895	253
542.556	251.5
543.217	265.5
543.878	244
544.539	241
545.199	235
545.86	232
546.519	248
547.179	223
547.838	224
548.498	231
549.157	224.5
549.815	217
550.474	209
551.132	221.5
551.789	219.493
552.447	221.434
553.104	202.706
553.76	206.669
554.418	211.274
555.074	216.506
555.73	207.666
556.385	206.653
557.041	208.869
557.697	200.732
558.351	192.703
559.006	197.548
559.661	203.765
560.315	195.447
560.969	187.628
561.622	202.135
562.276	194.026
562.928	177.603
563.582	193.708
564.235	196.73
564.887	189.277
565.539	186.58
566.19	187.907
566.842	187.26
567.493	180.405
568.143	176.234
568.794	182.746
569.445	182.264
570.095	170.349
570.745	173.657
571.394	177.647
572.043	180.557
572.692	170.577
573.341	180.699
573.99	177.331
574.638	173.606
575.286	167.016
575.934	164.818
576.581	171.921
577.229	177.997
577.876	165.8
578.521	180.673
579.168	175.936
579.814	170.621
580.46	166.762
581.106	169.214
581.751	163.198
582.395	158.333
583.04	170.558
583.684	171.623
584.329	171.053
584.973	176.067
585.616	163.212
586.26	166.69
586.902	163.237
587.545	160.432
588.187	158.37
588.83	169.503
589.472	161.25
590.113	164.377
590.755	165.182
591.396	160.464
592.036	153.456
592.677	160.264
593.318	155.254
593.958	152.911
594.597	153.13
595.237	152.504
595.875	157.151
596.515	153.428
597.154	150.828
597.792	152.752
598.431	155.478
599.067	152.493
599.706	154.511
600.342	147.598
600.981	151.131
601.617	143.833
602.254	153.157
602.889	144.495
603.526	149.852
604.161	150.005
604.797	148.675
605.432	142.651
606.067	138.75
606.7	143.032
607.335	146.297
607.97	138.419
608.603	141.887
609.236	144.418
609.87	149.451
610.503	150.607
611.136	143.871
611.768	140.708
612.401	148.232
613.032	154.121
613.664	146.171
614.295	158.993
614.925	162.316
615.556	154.883
616.188	159.054
616.818	156.805
617.447	174.472
618.077	166.966
618.707	167.23
619.335	164.497
619.965	164.396
620.593	160.195
621.221	156.766
621.849	157.375
622.477	160.979
623.105	161.662
623.731	156.941
624.359	162.593
624.986	164.613
625.612	160.35
626.238	166.871
626.863	157.636
627.489	156.635
628.114	152.133
628.74	152.564
629.365	156.204
629.989	158.288
630.613	151.522
631.237	156.997
631.86	154.921
632.484	153.193
633.107	153.873
633.73	148.161
634.353	150.379
634.975	156.673
635.597	154.956
636.219	158.433
636.84	159.636
637.461	156.585
638.082	163.419
638.704	155.528
639.323	154.484
639.944	160.078
640.564	154.971
641.183	158.32
641.803	149.89
642.421	149.029
643.04	156.397
643.658	158.023
644.278	156.443
644.895	158.319
645.513	154.223
646.13	150.058
646.747	151.393
647.364	163.543
647.981	155.148
648.597	154.39
649.213	156.495
649.829	151.756
650.444	150.158
651.06	159.874
651.675	158.132
652.289	152.815
652.904	160.581
653.518	156.128
654.132	162.773
654.745	149.524
655.332	149.5
655.991	147.5
656.65	149.5
657.308	147.5
657.966	157.5
658.624	153
659.282	153
659.938	151
660.596	147
661.253	152.5
661.909	154
662.565	146.5
663.222	147.5
663.878	156
664.534	152.5
665.189	150.5
665.843	145.5
666.498	141.5
667.152	158
667.807	153.5
668.461	140
669.114	149.5
669.768	149
670.421	150.5
671.074	140.5
671.727	146
672.38	146
673.031	138
673.683	151
674.335	138.5
674.987	147
675.638	159
676.288	150
676.939	150.5
677.589	141
678.239	141
678.89	163
679.539	145
680.188	146
680.838	149.5
681.485	140.5
682.134	142.5
682.782	137
683.431	144
684.079	141
684.726	150
685.372	143
686.02	147
686.667	137.5
687.313	140
687.959	143
688.604	145
689.25	143
689.896	135
690.542	137.5
691.186	136.5
691.83	141.5
692.475	144
693.119	130.5
693.762	138.5
694.406	139
695.05	140.5
695.692	147
696.335	145
696.978	143.5
697.621	132.5
698.262	129.5
698.904	126.5
699.546	124
700.187	131.5
700.827	130
701.468	137.5
702.108	143
702.749	147
703.388	140
704.028	130.5
704.667	126
705.306	139
705.945	125
706.584	127.5
707.222	136
707.861	119.5
708.498	134.5
709.135	135
709.773	130.5
710.41	133
711.047	130.5
711.684	129
712.319	136.5
712.956	129
713.592	134.5
714.227	136.5
714.862	134
715.498	123.5
716.131	130.5
716.767	134
717.4	132
718.034	131.5
718.668	124.5
719.301	127.5
719.933	123
720.567	124
721.199	131
721.832	130.5
722.464	136.5
723.096	130.5
723.727	133
724.359	136.5
724.989	129.5
725.621	128.5
726.251	135
726.881	131.5
727.511	133
728.14	126.5
728.77	137.5
729.399	127.5
730.029	124.5
730.657	124
731.286	128.5
731.913	123
732.541	122
733.17	124
733.797	140.5
734.423	124.5
735.05	129
735.677	128
736.304	116
736.929	128.5
737.556	118.5
738.181	134
738.806	120
739.431	121
740.056	124.5
740.68	115
741.305	117.5
741.928	126
742.552	129
743.175	124.5
743.798	119.5
744.422	125.5
745.045	126.5
745.667	114.5
746.289	122
746.91	121
747.532	111.5
748.154	127
748.775	126.5
749.395	130
750.017	122
750.637	117
751.257	119.5
751.877	111.5
752.495	113.5
753.115	124.5
753.734	128.5
754.353	128.5
754.972	120
755.59	122.5
756.207	123.5
756.825	126.5
757.443	128.5
758.06	120
758.677	117
759.293	127
759.91	128
760.526	115.5
761.142	122
761.758	114
762.373	123
762.988	129
763.603	116.5
764.218	120
764.831	118
765.446	128.5
766.059	116
766.673	128
767.286	119.5
767.899	115
768.512	122.5
769.124	114
769.736	114
770.349	121
770.96	116.5
771.572	120.5
772.182	110.5
772.794	112
773.404	115
774.015	127
774.625	107
775.235	130.5
775.845	114
776.453	120
777.063	113.5
777.671	114
778.279	111.51
778.888	127.475
779.496	109.54
780.104	118.481
780.712	116.951
781.319	117.235
781.925	130.84
782.532	114.489
783.138	118.459
783.745	114.426
784.351	119.833
784.956	118.899
785.561	111.527
786.168	121.127
786.773	117.806
787.376	115.374
787.981	118.445
788.586	122.608
789.189	116.592
789.792	113.545
790.396	113.38
790.999	119.829
791.602	110.681
792.204	113.771
792.807	113.357
793.408	110.812
794.01	115.317
794.611	109.162
795.213	115.988
795.814	111.781
796.414	115.497
797.014	115.375
797.616	114.977
798.216	112.823
798.814	107.462
799.414	119.839
800.014	112.461
800.612	120.274
801.21	110.458
801.809	112.276
802.407	118.85
803.005	118.767
803.602	116.455
804.2	114.569
804.797	118.64
805.393	114.216
805.99	111.654
806.586	116.061
807.183	104.46
807.778	111.775
808.373	105.604
808.969	116.652
809.564	107.62
810.158	112.341
810.753	116.882
811.347	114.053
811.941	114.226
812.534	114.584
813.127	113.787
813.721	115.129
814.314	111.413
814.906	115.784
815.499	110.347
816.091	111.334
816.682	109.822
817.274	110.164
817.865	110.006
818.456	106.601
819.047	111.454
819.637	108.522
820.227	110.343
820.817	115.366
821.407	116.16
821.997	116.318
822.586	108.874
823.175	110.907
823.764	112.312
824.352	109.701
824.941	111.49
825.528	115.329
826.116	107.75
826.703	114.119
827.289	112.502
827.876	112.91
828.463	112.441
829.049	110.891
829.636	112.885
830.221	113.219
830.807	111.625
831.392	114.854
831.977	111.041
832.562	111.396
833.147	107.769
833.73	110.151
834.315	116.441
834.899	110.534
835.482	107.736
836.064	110.212
836.648	113.986
837.231	110.733
837.813	105.474
838.395	104.725
838.977	111.473
839.558	109.892
840.14	103.851
840.721	105.21
841.302	109.652
841.882	112.393
842.463	108.229
843.043	111.977
843.622	114.945
844.202	113.57
844.78	108.917
845.36	105.021
845.939	107.764
846.518	112.694
847.095	112.707
847.673	102.37
848.25	112.309
848.829	109.566
849.406	111.121
849.983	110.626
850.558	110.291
851.135	104.133
851.712	112.297
852.287	112.944
852.863	106.695
853.438	111.174
854.013	107.181
854.587	107.374
855.163	104.738
855.736	111.841
856.31	107.329
856.884	110.795
857.458	110.893
858.031	103.859
858.603	107.439
859.177	111.285
859.749	107.631
860.321	116.877
860.893	106.868
861.465	107.451
862.036	106.669
862.608	108.473
863.179	115.172
863.749	108.327
864.32	107.466
864.889	108.573
865.459	113.05
866.028	112.032
866.598	109.535
867.167	122.674
867.736	108.366
868.304	107.139
868.872	109.675
869.44	112.243
870.009	108.448
870.576	112.607
870.908	101
871.522	104.5
872.135	108.5
872.747	109.5
873.36	113
873.972	108.5
874.585	116
875.196	107.5
875.808	105
876.419	109
877.03	110.5
877.641	110
878.252	112.5
878.863	112.5
879.472	111
880.083	105.5
880.692	104
881.301	116
881.911	113.5
882.52	115.5
883.128	106.5
883.737	108
884.344	116
884.952	109.5
885.559	101.5
886.167	104
886.774	102
887.382	115.5
887.988	117
888.594	110.5
889.2	105.5
889.806	101.5
890.412	103
891.017	104
891.623	109.5
892.227	116.5
892.832	108
893.436	103
894.04	107
894.644	106.5
895.248	109
895.851	106
896.454	97
897.058	114.5
897.66	101.5
898.263	106.5
898.864	99
899.466	106
900.068	105
900.67	109
901.271	114
901.872	112
902.471	104.5
903.072	111.5
903.673	109
904.272	110.5
904.872	103
905.471	99
906.07	114.5
906.669	114
907.268	103.5
907.866	108.5
908.464	115.5
909.061	109
909.659	107
910.257	102
910.854	102
911.452	114.5
912.048	109.5
912.644	113.5
913.24	111.5
913.836	107
914.432	95
915.027	116
915.622	114
916.216	108
916.812	110
917.406	112.5
917.999	108
918.593	107.5
919.188	117
919.78	104
920.373	112.5
920.966	118
921.559	109
922.151	109.5
922.744	112
923.335	117
923.927	111
924.518	107.5
925.109	109.5
925.701	109.5
926.29	117.5
926.881	108
927.471	124
928.061	131.5
928.651	113
929.24	126.5
929.829	124
930.417	118.5
931.007	123
931.595	127
932.182	132.5
932.77	137
933.358	146.5
933.946	141
934.532	140.5
935.12	154
935.706	151
936.292	145.5
936.878	166
937.464	143
938.05	158.5
938.635	154.5
939.221	154
939.805	153.5
940.39	147.5
940.974	152
941.557	166.5
942.142	153.5
942.725	154
943.309	151.5
943.892	153
944.475	155.5
945.056	144
945.639	145
946.222	150.5
946.803	149.5
947.384	151
947.966	147.5
948.547	154
949.128	144
949.708	134
950.289	144.5
950.869	150.5
951.448	139
952.028	147
952.608	137
953.186	141
953.765	144
954.343	150
954.922	151.5
955.5	139
956.078	144
956.656	151
957.232	146
957.81	141.5
958.386	143
958.963	143
959.539	148
960.114	133.5
960.691	146
961.267	129
961.842	144
962.417	145.5
962.991	137.5
963.566	135
964.139	131.5
964.714	140
965.287	143.5
965.861	137
966.434	134.5
967.007	138
967.58	144
968.153	128.5
968.725	134.5
969.297	140
969.868	135
970.44	139.5
971.011	141.5
971.583	129
972.153	147
972.723	143
973.294	144.5
973.864	129.5
974.433	131
975.003	144.5
975.573	140.5
976.141	137
976.71	135
977.278	138
977.846	128
978.415	137.5
978.982	122
979.55	121
980.117	134
980.684	126
981.25	122.5
981.817	137
982.384	124
982.949	114.5
983.515	131
984.08	122
984.645	129.5
985.21	115
985.775	122.5
986.34	119.5
986.904	114
987.468	115
988.031	116
988.595	117.5
989.158	119
989.721	111
990.284	120
990.846	109
991.408	111.5
991.97	108.5
992.532	108.5
993.093	101.5
993.655	101.5
994.215	110.5
994.776	108.5
995.336	111.5
995.896	107
996.457	106.5
997.016	103
997.576	107.5
998.135	110
998.694	100.5
999.253	92.5
999.811	106